2023-10-23 01:25:01.998481: I tensorflow/core/platform/cpu_feature_guard.cc:182] This TensorFlow binary is optimized to use available CPU instructions in performance-critical operations.
To enable the following instructions: AVX2 FMA, in other operations, rebuild TensorFlow with the appropriate compiler flags.
2023-10-23 01:25:05.459900: W tensorflow/compiler/tf2tensorrt/utils/py_utils.cc:38] TF-TRT Warning: Could not find TensorRT
2023-10-23 01:25:27.987715: I tensorflow/core/common_runtime/gpu/gpu_device.cc:1639] Created device /job:localhost/replica:0/task:0/device:GPU:0 with 79089 MB memory:  -> device: 0, name: NVIDIA A100-SXM4-80GB, pci bus id: 0000:01:00.0, compute capability: 8.0
2023-10-23 01:25:27.988705: I tensorflow/core/common_runtime/gpu/gpu_device.cc:1639] Created device /job:localhost/replica:0/task:0/device:GPU:1 with 79089 MB memory:  -> device: 1, name: NVIDIA A100-SXM4-80GB, pci bus id: 0000:41:00.0, compute capability: 8.0
Epoch 1/100
2023-10-23 01:25:43.769749: E tensorflow/compiler/xla/stream_executor/cuda/cuda_dnn.cc:425] Loaded runtime CuDNN library: 8.5.0 but source was compiled with: 8.6.0.  CuDNN library needs to have matching major version and equal or higher minor version. If using a binary install, upgrade your CuDNN library.  If building from sources, make sure the library loaded at runtime is compatible with the version specified during compile configuration.
2023-10-23 01:25:43.770712: W tensorflow/core/framework/op_kernel.cc:1828] OP_REQUIRES failed at conv_ops_impl.h:770 : UNIMPLEMENTED: DNN library is not found.
Traceback (most recent call last):
  File "my_script_name.py", line 56, in <module>
    model.fit(npImageList,ytrain,verbose=1,epochs=100)
  File "/home/mamcinerney/.local/lib/python3.8/site-packages/keras/src/utils/traceback_utils.py", line 70, in error_handler
    raise e.with_traceback(filtered_tb) from None
  File "/home/mamcinerney/.local/lib/python3.8/site-packages/tensorflow/python/eager/execute.py", line 53, in quick_execute
    tensors = pywrap_tfe.TFE_Py_Execute(ctx._handle, device_name, op_name,
tensorflow.python.framework.errors_impl.UnimplementedError: Graph execution error:

Detected at node 'convnext_tiny/convnext_tiny_stem/convnext_tiny_stem_conv/Conv2D' defined at (most recent call last):
    File "my_script_name.py", line 56, in <module>
      model.fit(npImageList,ytrain,verbose=1,epochs=100)
    File "/home/mamcinerney/.local/lib/python3.8/site-packages/keras/src/utils/traceback_utils.py", line 65, in error_handler
      return fn(*args, **kwargs)
    File "/home/mamcinerney/.local/lib/python3.8/site-packages/keras/src/engine/training.py", line 1742, in fit
      tmp_logs = self.train_function(iterator)
    File "/home/mamcinerney/.local/lib/python3.8/site-packages/keras/src/engine/training.py", line 1338, in train_function
      return step_function(self, iterator)
    File "/home/mamcinerney/.local/lib/python3.8/site-packages/keras/src/engine/training.py", line 1322, in step_function
      outputs = model.distribute_strategy.run(run_step, args=(data,))
    File "/home/mamcinerney/.local/lib/python3.8/site-packages/keras/src/engine/training.py", line 1303, in run_step
      outputs = model.train_step(data)
    File "/home/mamcinerney/.local/lib/python3.8/site-packages/keras/src/engine/training.py", line 1080, in train_step
      y_pred = self(x, training=True)
    File "/home/mamcinerney/.local/lib/python3.8/site-packages/keras/src/utils/traceback_utils.py", line 65, in error_handler
      return fn(*args, **kwargs)
    File "/home/mamcinerney/.local/lib/python3.8/site-packages/keras/src/engine/training.py", line 569, in __call__
      return super().__call__(*args, **kwargs)
    File "/home/mamcinerney/.local/lib/python3.8/site-packages/keras/src/utils/traceback_utils.py", line 65, in error_handler
      return fn(*args, **kwargs)
    File "/home/mamcinerney/.local/lib/python3.8/site-packages/keras/src/engine/base_layer.py", line 1150, in __call__
      outputs = call_fn(inputs, *args, **kwargs)
    File "/home/mamcinerney/.local/lib/python3.8/site-packages/keras/src/utils/traceback_utils.py", line 96, in error_handler
      return fn(*args, **kwargs)
    File "/home/mamcinerney/.local/lib/python3.8/site-packages/keras/src/engine/functional.py", line 512, in call
      return self._run_internal_graph(inputs, training=training, mask=mask)
    File "/home/mamcinerney/.local/lib/python3.8/site-packages/keras/src/engine/functional.py", line 669, in _run_internal_graph
      outputs = node.layer(*args, **kwargs)
    File "/home/mamcinerney/.local/lib/python3.8/site-packages/keras/src/utils/traceback_utils.py", line 65, in error_handler
      return fn(*args, **kwargs)
    File "/home/mamcinerney/.local/lib/python3.8/site-packages/keras/src/engine/training.py", line 569, in __call__
      return super().__call__(*args, **kwargs)
    File "/home/mamcinerney/.local/lib/python3.8/site-packages/keras/src/utils/traceback_utils.py", line 65, in error_handler
      return fn(*args, **kwargs)
    File "/home/mamcinerney/.local/lib/python3.8/site-packages/keras/src/engine/base_layer.py", line 1150, in __call__
      outputs = call_fn(inputs, *args, **kwargs)
    File "/home/mamcinerney/.local/lib/python3.8/site-packages/keras/src/utils/traceback_utils.py", line 96, in error_handler
      return fn(*args, **kwargs)
    File "/home/mamcinerney/.local/lib/python3.8/site-packages/keras/src/engine/sequential.py", line 405, in call
      return super().call(inputs, training=training, mask=mask)
    File "/home/mamcinerney/.local/lib/python3.8/site-packages/keras/src/engine/functional.py", line 512, in call
      return self._run_internal_graph(inputs, training=training, mask=mask)
    File "/home/mamcinerney/.local/lib/python3.8/site-packages/keras/src/engine/functional.py", line 669, in _run_internal_graph
      outputs = node.layer(*args, **kwargs)
    File "/home/mamcinerney/.local/lib/python3.8/site-packages/keras/src/utils/traceback_utils.py", line 65, in error_handler
      return fn(*args, **kwargs)
    File "/home/mamcinerney/.local/lib/python3.8/site-packages/keras/src/engine/base_layer.py", line 1150, in __call__
      outputs = call_fn(inputs, *args, **kwargs)
    File "/home/mamcinerney/.local/lib/python3.8/site-packages/keras/src/utils/traceback_utils.py", line 96, in error_handler
      return fn(*args, **kwargs)
    File "/home/mamcinerney/.local/lib/python3.8/site-packages/keras/src/layers/convolutional/base_conv.py", line 290, in call
      outputs = self.convolution_op(inputs, self.kernel)
    File "/home/mamcinerney/.local/lib/python3.8/site-packages/keras/src/layers/convolutional/base_conv.py", line 262, in convolution_op
      return tf.nn.convolution(
Node: 'convnext_tiny/convnext_tiny_stem/convnext_tiny_stem_conv/Conv2D'
DNN library is not found.
	 [[{{node convnext_tiny/convnext_tiny_stem/convnext_tiny_stem_conv/Conv2D}}]] [Op:__inference_train_function_27582]
I am done
